Workbook

Sheet Sheet1
C2: Stt | D2: Thời Gian | E2: Part No | F2: Đơn Giá | G2: P/O NO | H2: Số Lượng | I2: Total | J2: Trạng Thái | M2: Trạng thái | N2: Tháng Thanh Toán
C3: =ROW()-2 -> 1 | E3: PF2M711-02-A-M | F3: 3435000 | G3: VH26M0233 | H3: 36 | I3: =H3*F3 -> 123660000 | J3: Đã nhập kho | K3: 8 | L3: =K3*I3% -> 9892800 | P3: =SUM(L:L) -> 231077360
C4: =ROW()-2 -> 2 | E4: PF2M711-02-A-M | F4: 3435000 | G4: VH26M0231 | H4: 36 | I4: =H4*F4 -> 123660000 | J4: Đã nhập kho | K4: 8 | L4: =K4*I4% -> 9892800
C5: =ROW()-2 -> 3 | E5: KQ2L04-02GS1 | F5: 108000 | G5: VH26M0197 | H5: 36 | I5: =H5*F5 -> 3888000 | J5: Đã nhập kho | K5: 8 | L5: =K5*I5% -> 311040
C6: =ROW()-2 -> 4 | E6: KQ2L04-02GS1 | F6: 108000 | G6: VH26M0251 | H6: 36 | I6: =H6*F6 -> 3888000 | J6: Đã nhập kho | K6: 8 | L6: =K6*I6% -> 311040
C7: =ROW()-2 -> 5 | E7: CUJB20-PS | F7: 189000 | G7: VH26K0649 | H7: 30 | I7: =H7*F7 -> 5670000 | J7: Đã nhập kho | K7: 8 | L7: =K7*I7% -> 453600
C8: =ROW()-2 -> 6 | E8: CUJB20-PS | F8: 189000 | G8: VH26M0744 | H8: 30 | I8: =H8*F8 -> 5670000 | J8: Đã nhập kho | K8: 8 | L8: =K8*I8% -> 453600
C9: =ROW()-2 -> 7 | E9: CJP2B16D-PS | F9: 119000 | G9: VH26K0436 | H9: 30 | I9: =H9*F9 -> 3570000 | J9: Đã nhập kho | K9: 8 | L9: =K9*I9% -> 285600
C10: =ROW()-2 -> 8 | E10: CJP2B16D-PS | F10: 119000 | G10: VH26M0482 | H10: 30 | I10: =H10*F10 -> 3570000 | J10: Đã nhập kho | K10: 8 | L10: =K10*I10% -> 285600
C11: =ROW()-2 -> 9 | E11: CJP2B16D-PS | F11: 119000 | G11: VH26T0660 | H11: 50 | I11: =H11*F11 -> 5950000 | J11: Đã nhập kho | K11: 8 | L11: =K11*I11% -> 476000
C12: =ROW()-2 -> 10 | E12: CU10D-PS | F12: 66000 | G12: VH26M0066 | H12: 80 | I12: =H12*F12 -> 5280000 | J12: Đã nhập kho | K12: 8 | L12: =K12*I12% -> 422400
C13: =ROW()-2 -> 11 | E13: CU10D-PS | F13: 66000 | G13: VH26M0743 | H13: 50 | I13: =H13*F13 -> 3300000 | J13: Đã nhập kho | K13: 8 | L13: =K13*I13% -> 264000
C14: =ROW()-2 -> 12 | E14: CQSWB12-PS | F14: 71000 | G14: VH26K0463 | H14: 20 | I14: =H14*F14 -> 1420000 | J14: Đã nhập kho | K14: 8 | L14: =K14*I14% -> 113600
C15: =ROW()-2 -> 13 | E15: CQSWB12-PS | F15: 71000 | G15: VH26M0527 | H15: 20 | I15: =H15*F15 -> 1420000 | J15: Đã nhập kho | K15: 8 | L15: =K15*I15% -> 113600
... C85: =ROW()-2 -> 83 | E85: CY3B15-PS | F85: 246000 | G85: VH26B0177 | H85: 20 | I85: =H85*F85 -> 4920000 | J85: Chưa Nhập kho | K85: 8 | L85: =K85*I85% -> 393600
C86: =ROW()-2 -> 84 | D86: 12/2025 | E86: PF2M711-02-A-M | F86: 3435000 | G86: VH26Y0389 | H86: 39 | I86: =H86*F86 -> 133965000 | K86: 8 | L86: =K86*I86% -> 10717200
C87: =ROW()-2 -> 85 | D87: 12/2025 | E87: KQ2L04-02GS1 | F87: 108000 | G87: VH26Y0391 | H87: 70 | I87: =H87*F87 -> 7560000 | K87: 8 | L87: =K87*I87% -> 604800
C88: =ROW()-2 -> 86 | D88: 12/2025 | E88: TU0425BU-100 | F88: 978000 | G88: VH26Y0339 | H88: 4 | I88: =H88*F88 -> 3912000 | K88: 8 | L88: =K88*I88% -> 312960
C89: =ROW()-2 -> 87 | D89: 12/2025 | E89: TU0425BU-100 | F89: 978000 | G89: VH84Y0092 | H89: 4 | I89: =H89*F89 -> 3912000 | K89: 8 | L89: =K89*I89% -> 312960
C90: =ROW()-2 -> 88 | D90: 12/2025 | E90: TU0425C-100 | F90: 978000 | G90: VH25Y0032 | H90: 1 | I90: =H90*F90 -> 978000 | K90: 8 | L90: =K90*I90% -> 78240
C91: =ROW()-2 -> 89 | D91: 12/2025 | E91: MXH2B6-5-XC22 | F91: 3105000 | G91: VH26F0352 | H91: 10 | I91: =H91*F91 -> 31050000 | K91: 8 | L91: =K91*I91% -> 2484000
C92: =ROW()-2 -> 90 | D92: 12/2025 | E92: CU10D-PS | F92: =VLOOKUP(E92,Sheet2!$H$2:$I$30,2,0) -> 66000 | G92: VH26C0059 | H92: 20 | I92: =H92*F92 -> 1320000 | K92: 8 | L92: =K92*I92% -> 105600
C93: =ROW()-2 -> 91 | D93: 12/2025 | E93: CY3R10-PS | F93: =VLOOKUP(E93,Sheet2!$H$2:$I$30,2,0) -> 714000 | G93: VH26B0179 | H93: 20 | I93: =H93*F93 -> 14280000 | K93: 8 | L93: =K93*I93% -> 1142400
C94: =ROW()-2 -> 92 | D94: 12/2025 | E94: CXSWL10APS | F94: =VLOOKUP(E94,Sheet2!$H$2:$I$30,2,0) -> 284000 | G94: VH26B0212 | H94: 10 | I94: =H94*F94 -> 2840000 | K94: 8 | L94: =K94*I94% -> 227200
C95: =ROW()-2 -> 93 | D95: 12/2025 | E95: MHL10-PS | F95: =VLOOKUP(E95,Sheet2!$H$2:$I$30,2,0) -> 628000 | G95: VH26B0250 | H95: 10 | I95: =H95*F95 -> 6280000 | K95: 8 | L95: =K95*I95% -> 502400
C96: =ROW()-2 -> 94 | D96: 11/2025 | E96: AS1311F-M5-04A | F96: =VLOOKUP(E96,Sheet2!$H$2:$I$30,2,0) -> 174000 | G96: VH26X0072 | H96: 235 | I96: =H96*F96 -> 40890000 | K96: 5 | L96: =K96*I96% -> 2044500
C97: =ROW()-2 -> 95 | D97: 11/2025 | E97: AS1311F-M5-04A | F97: =VLOOKUP(E97,Sheet2!$H$2:$I$30,2,0) -> 174000 | G97: VH26X0076 | H97: 330 | I97: =H97*F97 -> 57420000 | K97: 5 | L97: =K97*I97% -> 2871000
C98: =ROW()-2 -> 96 | D98: 11/2025 | E98: AS1311F-M5-04A | F98: =VLOOKUP(E98,Sheet2!$H$2:$I$30,2,0) -> 174000 | G98: VH26X0087 | H98: 180 | I98: =H98*F98 -> 31320000 | K98: 5 | L98: =K98*I98% -> 1566000
C99: =ROW()-2 -> 97 | D99: 02/2026 | E99: PF2M711-02-A-M | F99: 3435000 | G99: VH26F0250 | H99: 6 | I99: =H99*F99 -> 20610000 | K99: 8 | L99: =K99*I99% -> 1648800
C100: =ROW()-2 -> 98 | D100: 02/2026 | E100: KQ2L04-02GS1 | F100: 108000 | G100: VH26E0317 | H100: 9 | I100: =H100*F100 -> 972000 | K100: 8 | L100: =K100*I100% -> 77760
C101: =ROW()-2 -> 99 | D101: 02/2026 | E101: KQ2L04-02GS1 | F101: 108000 | G101: VH26F0091 | H101: 9 | I101: =H101*F101 -> 972000 | K101: 8 | L101: =K101*I101% -> 77760
C102: =ROW()-2 -> 100 | D102: 02/2026 | E102: TU0425BU-100 | F102: 978000 | G102: VH84E0133 | H102: 5 | I102: =H102*F102 -> 4890000 | K102: 8 | L102: =K102*I102% -> 391200
C103: =ROW()-2 -> 101 | D103: 02/2026 | E103: TU0425C-100 | F103: 978000 | G103: VH8CF0004 | H103: 1 | I103: =H103*F103 -> 978000 | K103: 8 | L103: =K103*I103% -> 78240
C104: =ROW()-2 -> 102 | D104: 02/2026 | E104: MXH2B6-5-XC22 | F104: 3105000 | G104: VH26E0325 | H104: 20 | I104: =H104*F104 -> 62100000 | K104: 8 | L104: =K104*I104% -> 4968000
C105: =ROW()-2 -> 103 | D105: 02/2026 | E105: CQSB12-PS | F105: =VLOOKUP(E105,Sheet2!$H$2:$I$30,2,0) -> 57000 | G105: VH26E0313 | H105: 50 | I105: =H105*F105 -> 2850000 | K105: 8 | L105: =K105*I105% -> 228000
C106: =ROW()-2 -> 104 | D106: 02/2026 | E106: CQSB12-PS | F106: =VLOOKUP(E106,Sheet2!$H$2:$I$30,2,0) -> 57000 | G106: VH2620114 | H106: 50 | I106: =H106*F106 -> 2850000 | K106: 8 | L106: =K106*I106% -> 228000
C107: =ROW()-2 -> 105 | D107: 02/2026 | E107: CY3R10-PS | F107: =VLOOKUP(E107,Sheet2!$H$2:$I$30,2,0) -> 714000 | G107: VH26E0454 | H107: 50 | I107: =H107*F107 -> 35700000 | K107: 8 | L107: =K107*I107% -> 2856000
C108: =ROW()-2 -> 106 | D108: 02/2026 | E108: CY3R10-PS | F108: =VLOOKUP(E108,Sheet2!$H$2:$I$30,2,0) -> 714000 | G108: VH2620129 | H108: 50 | I108: =H108*F108 -> 35700000 | K108: 8 | L108: =K108*I108% -> 2856000
C109: =ROW()-2 -> 107 | D109: 02/2026 | E109: CXSWM10-PS | F109: =VLOOKUP(E109,Sheet2!$H$2:$I$30,2,0) -> 284000 | G109: VH26E0328 | H109: 30 | I109: =H109*F109 -> 8520000 | K109: 8 | L109: =K109*I109% -> 681600
C110: =ROW()-2 -> 108 | D110: 02/2026 | E110: CXSWM10-PS | F110: =VLOOKUP(E110,Sheet2!$H$2:$I$30,2,0) -> 284000 | G110: VH2620123 | H110: 50 | I110: =H110*F110 -> 14200000 | K110: 8 | L110: =K110*I110% -> 1136000
...

Sheet Sheet3
E2: CXSWM10-PS
E3: CXSM15-PS
E4: CUW16D-PS
E5: CXSWL10APS
E6: CQ2B63-PS
E7: CY3R15-PS
E8: MXQ20-PS
E9: MHL10-PS
E10: CY3B15-PS
E11: CY3R10-PS
E12: PF2M711-02-A-M
E13: KQ2L04-02GS1
... E21: TU0425C-100

Sheet Sheet2
H2: PF2M711-02-A-M | I2: =VLOOKUP(H2,Sheet1!$E$3:$F$95,2,0) -> 3435000 | K2: PF2M711-02-A-M | L2: 3435000
E3: MXH2B6-5-XC22 | H3: KQ2L04-02GS1 | I3: =VLOOKUP(H3,Sheet1!$E$3:$F$95,2,0) -> 108000 | K3: KQ2L04-02GS1 | L3: 108000
E4: RCP2W-RA6C-I-56P-4-50-P1-P | H4: TU0425BU-100 | I4: =VLOOKUP(H4,Sheet1!$E$3:$F$95,2,0) -> 978000 | K4: TU0425BU-100 | L4: 978000
E5: PF2M711-02-A-M | H5: TU0425C-100 | I5: =VLOOKUP(H5,Sheet1!$E$3:$F$95,2,0) -> 978000 | K5: TU0425BU-100 | L5: 978000
E6: AB-2505E | H6: MXH2B6-5-XC22 | I6: =VLOOKUP(H6,Sheet1!$E$3:$F$95,2,0) -> 3105000 | K6: TU0425C-100 | L6: 978000
E7: MXQ12A-75ZHF | H7: CUJB20-PS | I7: =VLOOKUP(H7,Sheet1!$E$3:$F$95,2,0) -> 189000 | K7: MXH2B6-5-XC22 | L7: 3105000
E8: 3HR-4/3FAUC | H8: CJP2B16D-PS | I8: =VLOOKUP(H8,Sheet1!$E$3:$F$95,2,0) -> 119000 | K8: CUJB20-PS | L8: 189000
E9: MXQ16L-50AS | H9: CU10D-PS | I9: =VLOOKUP(H9,Sheet1!$E$3:$F$95,2,0) -> 66000 | K9: CJP2B16D-PS | L9: 119000
E10: MXQ20-10A | H10: CQSWB12-PS | I10: =VLOOKUP(H10,Sheet1!$E$3:$F$95,2,0) -> 71000 | K10: CU10D-PS | L10: 66000
E11: MXQ16-50AS | H11: CQSB12-PS | I11: =VLOOKUP(H11,Sheet1!$E$3:$F$95,2,0) -> 57000 | K11: CQSWB12-PS | L11: 71000
E12: KQ2L04-02GS1 | H12: CY3R10-PS | I12: =VLOOKUP(H12,Sheet1!$E$3:$F$95,2,0) -> 714000 | K12: CQSB12-PS | L12: 57000
E13: MXQ8-10 | H13: CXSWM10-PS | I13: =VLOOKUP(H13,Sheet1!$E$3:$F$95,2,0) -> 284000 | K13: CY3R10-PS | L13: 714000
E14: TB-02-C-SWR-CHI | H14: CXSM15-PS | I14: =VLOOKUP(H14,Sheet1!$E$3:$F$95,2,0) -> 189000 | K14: CXSWM10-PS | L14: 284000
... E21: CXSM15-PS | H21: CY3B15-PS | I21: =VLOOKUP(H21,Sheet1!$E$3:$F$95,2,0) -> 246000 | K21: MHL10-PS | L21: 628000
E22: CUW16D-PS | H22: AS1311F-M5-04A | I22: 174000 | K22: CY3B15-PS | L22: 246000
E23: CXSWL10APS | K23: AS1311F-M5-04A | L23: 174000
E24: CQ2B63-PS
E25: CY3R15-PS
E26: MXQ20-PS
E27: AS1201F-M5-02A
E28: RCP2-SA5R-I-42P-12-250-P1-P-ML
E29: CJP2B16D-PS
E30: CU10D-PS
E31: CDQSWB20-5DC
E32: CQSWB12-PS
E33: CDQSB16-75DC
E34: PDR-080
E35: MHL10-PS
... E40: KQ2C-04GA
